Workbook

Sheet Structure
C1: Fixed Allowance
A2: Level | B2: Basic Salary | C2: Position Allowance | D2: Transport Allowance | E2: Communication Allowance | F2: Meal Allowance | G2: PPh 21 Allowance | H2: Total Fixed Income | I2: Variable Allowance
A3: BOD | C3: 0 | D3: 0 | E3: 0 | F3: 0 | H3: =SUM(B3:F3) -> 0 | I3: Bonus Kinerja, THR
A4: Manager A | C4: 0 | D4: 0 | E4: 0 | F4: 0 | H4: =SUM(B4:F4) -> 0 | I4: Bonus Kinerja, THR
A5: Manager B | C5: 0 | D5: 0 | E5: 0 | F5: 0 | H5: =SUM(B5:F5) -> 0 | I5: Bonus Kinerja, THR
A6: Manager C | C6: 0 | D6: 0 | E6: 0 | F6: 0 | H6: =SUM(B6:F6) -> 0 | I6: Bonus Kinerja, THR
A7: Supervisor A | C7: 0 | D7: 0 | E7: 0 | F7: 0 | H7: =SUM(B7:F7) -> 0 | I7: Insentif Tim, Lembur, THR
A8: Supervisor B | C8: 0 | D8: 0 | E8: 0 | F8: 0 | H8: =SUM(B8:F8) -> 0 | I8: Insentif Tim, Lembur, THR
A9: Supervisor C | C9: 0 | D9: 0 | E9: 0 | F9: 0 | H9: =SUM(B9:F9) -> 0 | I9: Insentif Tim, Lembur, THR
A10: Staff A | C10: 0 | D10: 0 | E10: 0 | F10: 0 | H10: =SUM(B10:F10) -> 0 | I10: Insentif Individu, Lembur, THR
A11: Staff B | C11: 0 | D11: 0 | E11: 0 | F11: 0 | H11: =SUM(B11:F11) -> 0 | I11: Insentif Individu, Lembur, THR
A12: Staff C | C12: 0 | D12: 0 | E12: 0 | F12: 0 | H12: =SUM(B12:F12) -> 0 | I12: Insentif Individu, Lembur, THR
A13: Non-Staff A | C13: 0 | D13: 0 | E13: 0 | F13: 0 | H13: =SUM(B13:F13) -> 0 | I13: Lembur, THR
A14: Non-Staff B | C14: 0 | D14: 0 | E14: 0 | F14: 0 | H14: =SUM(B14:F14) -> 0 | I14: Lembur, THR
A15: Non-Staff C | C15: 0 | D15: 0 | E15: 0 | F15: 0 | H15: =SUM(B15:F15) -> 0 | I15: Lembur, THR

Sheet Transfer
A1: =Salary!A1 -> PT. Kalapa Teknologi Putera
A2: =Salary!A2&TEXT(Salary!$B$2,"MMMM-YYYY") -> Periode : April-2026
A6: Sum of Net Salary
A7: Bank | B7: Bank Account | C7: Account Holder | D7: Total
A8: Grand Total

Sheet PPh 21
A1: =Salary!A1 -> PT. Kalapa Teknologi Putera
A2: =Salary!A2&TEXT(Salary!$B$2,"MMMM-YYYY") -> Periode : April-2026
F6: Values
A7: KTP ID | B7: Gov Tax File No | C7: Employee Name | D7: Tax Status | E7: Position | F7: Sum of Gross Salary for Tax | G7: Sum of Tax
A8: (blank) | B8: (blank) | C8: (blank) | D8: (blank) | E8: (blank)
A9: Grand Total

Sheet Salary
A1: PT. Kalapa Teknologi Putera | R1: BPJS KESEHATAN | AF1: BPJS KESEHATAN | AI1: Deduction Pinjaman Karyawan
A2: Periode : | B2: 46113
A3: Working Days : | B3: 19
N4: 0.003 | O4: 0.0024 | P4: 0.037 | Q4: 0.02 | R4: 0.04 | Z4: =N4 -> 0.003 | AA4: =O4 -> 0.0024 | AB4: 0.02 | AC4: =P4 -> 0.037 | AD4: =Q4 -> 0.02 | AE4: 0.01 | AF4: =R4 -> 0.04 | AG4: 0.01 | BD4: For Overtime Calculation
A5: No | B5: Employee Name | C5: Employee ID | D5: KTP ID | E5: Gov Tax File No | F5: Position | G5: Department | H5: Employment Status | I5: Join Date | J5: Terminate Date | K5: Length Of Service | L5: Basic Salary | M5: Prorated Salary | N5: JKM | O5: JKK | P5: JHT Company | Q5: JP Company | R5: BPJS Company | S5: Adjustment + | T5: Skill Allowance | U5: attandance Allowance | V5: Meal Allowance | W5: Tax Allowance | X5: Insentif | Y5: Total Income | Z5: JKM | AA5: JKK | AB5: JHT Employee | AC5: JHT Company | AD5: JP Company | AE5: JP Employee | AF5: BPJS Company | AG5: BPJS Employee | AH5: Absence | AI5: Cut-Off | AJ5: Total Deduction | AK5: Tax | AL5: Tax Penalty | AM5: Net Salary | AN5: Bank | AO5: Location | AP5: Account Holder | AQ5: Bank Account | AR5: Tax Status | AS5: Type of TER | AT5: Tax Rate (TER) | AU5: PPh 21 TER | AV5: Gross Salary for Tax | AX5: BPJS TK | AY5: BPJS Kes | AZ5: Salary for BPJS | BB5: Absence (Days) | BD5: Sum of OT Days | BE5: Sum of OT Hours | BF5: OT Hours for Calculation | BG5: Salary per Hour
A6: 1 | B6: Fakhrizal Milnawan | F6: Project SKF | G6: Telemarketing | H6: Kontrak | I6: 45873 | L6: 5729876 | M6: 5729876 | N6: =M6*$N$4 -> 17189.628 | O6: =M6*$O$4 -> 13751.702 | P6: =M6*$P$4 -> 212005.41 | Q6: =M6*$Q$4 -> 114597.52 | R6: =L6*$R$4 -> 229195.04 | T6: 500000 | U6: 100000 | Y6: =SUM(M6:X6) -> 6916615.3 | Z6: =N6 -> 17189.628 | AA6: =O6 -> 13751.702 | AB6: =M6*$AB$4 -> 114597.52 | AC6: =P6 -> 212005.41 | AD6: =Q6 -> 114597.52 | AE6: =M6*$AE$4 -> 57298.76 | AF6: =R6 -> 229195.04 | AG6: =L6*$AG$4 -> 57298.76 | AH6: 0 | AJ6: =SUM(Z6:AI6) -> 815934.34 | AK6: =AU6 -> 65900 | AM6: =Y6-AJ6-AK6-AL6 -> 6034781 | AR6: TK/0 | AS6: =IFERROR(VLOOKUP($AR6,TER!$G$6:$H$17,2,FALSE),"") -> TER A | AT6: {=SUMPRODUCT(TER!$E$6:$E$132*(TER!$A$6:$A$132=$AS6)*(TER!$B$6:$B$132<$AV6)*((TER!$D$6:$D$132>=$AV6)+(TER!$D$6:$D$132="")))} -> 0.01 | AU6: =ROUNDDOWN(AT6*AV6,0) -> 65900 | AV6: =Y6-AC6-AD6-AH6-AI6 -> 6590012.4 | AX6: Terdaftar | AY6: Terdaftar | AZ6: 5700000 | BF6: =($BE6*2)-(0.5*$BD6) -> 0 | BG6: =ROUND(L6/173,2) -> 33120.67
A7: =A6+1 -> 2 | B7: Pinka Saninta | F7: Project SKF | G7: Customer Service Representative | H7: Kontrak | I7: 45945 | L7: 8500000 | M7: 8500000 | N7: =M7*$N$4 -> 25500 | O7: =M7*$O$4 -> 20400 | P7: =M7*$P$4 -> 314500 | Q7: =M7*$Q$4 -> 170000 | R7: =L7*$R$4 -> 340000 | T7: 0 | U7: 500000 | Y7: =SUM(M7:X7) -> 9870400 | Z7: =N7 -> 25500 | AA7: =O7 -> 20400 | AB7: =M7*$AB$4 -> 170000 | AC7: =P7 -> 314500 | AD7: =Q7 -> 170000 | AE7: =M7*$AE$4 -> 85000 | AF7: =R7 -> 340000 | AG7: =L7*$AG$4 -> 85000 | AH7: 0 | AJ7: =SUM(Z7:AI7) -> 1210400 | AK7: =AU7 -> 164253 | AM7: =Y7-AJ7-AK7-AL7 -> 8495747 | AR7: TK/0 | AS7: =IFERROR(VLOOKUP($AR7,TER!$G$6:$H$17,2,FALSE),"") -> TER A | AT7: {=SUMPRODUCT(TER!$E$6:$E$132*(TER!$A$6:$A$132=$AS7)*(TER!$B$6:$B$132<$AV7)*((TER!$D$6:$D$132>=$AV7)+(TER!$D$6:$D$132="")))} -> 0.0175 | AU7: =ROUNDDOWN(AT7*AV7,0) -> 164253 | AV7: =Y7-AC7-AD7-AH7-AI7 -> 9385900 | AX7: Terdaftar | AY7: Terdaftar | AZ7: 5250000 | BF7: =($BE7*2)-(0.5*$BD7) -> 0 | BG7: =ROUND(L7/173,2) -> 49132.95
A8: =A7+1 -> 3 | B8: Luthfi | F8: Project SKF | G8: Customer Service Representative | H8: Kontrak | I8: 45945 | L8: 8500000 | M8: 8500000 | N8: =M8*$N$4 -> 25500 | O8: =M8*$O$4 -> 20400 | P8: =M8*$P$4 -> 314500 | Q8: =M8*$Q$4 -> 170000 | R8: =L8*$R$4 -> 340000 | T8: 0 | U8: 500000 | Y8: =SUM(M8:X8) -> 9870400 | Z8: =N8 -> 25500 | AA8: =O8 -> 20400 | AB8: =M8*$AB$4 -> 170000 | AC8: =P8 -> 314500 | AD8: =Q8 -> 170000 | AE8: =M8*$AE$4 -> 85000 | AF8: =R8 -> 340000 | AG8: =L8*$AG$4 -> 85000 | AH8: 0 | AJ8: =SUM(Z8:AI8) -> 1210400 | AK8: =AU8 -> 164253 | AM8: =Y8-AJ8-AK8-AL8 -> 8495747 | AR8: TK/0 | AS8: =IFERROR(VLOOKUP($AR8,TER!$G$6:$H$17,2,FALSE),"") -> TER A | AT8: {=SUMPRODUCT(TER!$E$6:$E$132*(TER!$A$6:$A$132=$AS8)*(TER!$B$6:$B$132<$AV8)*((TER!$D$6:$D$132>=$AV8)+(TER!$D$6:$D$132="")))} -> 0.0175 | AU8: =ROUNDDOWN(AT8*AV8,0) -> 164253 | AV8: =Y8-AC8-AD8-AH8-AI8 -> 9385900 | AX8: Terdaftar | AY8: Terdaftar | AZ8: 5250000 | BF8: =($BE8*2)-(0.5*$BD8) -> 0 | BG8: =ROUND(L8/173,2) -> 49132.95
A9: =A8+1 -> 4 | B9: Simon Wijaya Ingratubun | F9: Project SKF | G9: Teknisi Remanufacturing | H9: Kontrak | I9: 46127 | L9: 6729876 | M9: 1416816 | N9: =M9*$N$4 -> 4250.448 | O9: =M9*$O$4 -> 3400.3584 | P9: =M9*$P$4 -> 52422.192 | Q9: =M9*$Q$4 -> 28336.32 | R9: =L9*$R$4 -> 269195.04 | T9: 0 | U9: 21052.632 | Y9: =SUM(M9:X9) -> 1795473 | Z9: =N9 -> 4250.448 | AA9: =O9 -> 3400.3584 | AB9: =M9*$AB$4 -> 28336.32 | AC9: =P9 -> 52422.192 | AD9: =Q9 -> 28336.32 | AE9: =M9*$AE$4 -> 14168.16 | AF9: =R9 -> 269195.04 | AG9: =L9*$AG$4 -> 67298.76 | AH9: 0 | AI9: 0 | AJ9: =SUM(Z9:AI9) -> 467407.6 | AK9: =AU9 -> 0 | AM9: =Y9-AJ9-AK9-AL9 -> 1328065.4 | AR9: TK/0 | AS9: =IFERROR(VLOOKUP($AR9,TER!$G$6:$H$17,2,FALSE),"") -> TER A | AT9: {=SUMPRODUCT(TER!$E$6:$E$132*(TER!$A$6:$A$132=$AS9)*(TER!$B$6:$B$132<$AV9)*((TER!$D$6:$D$132>=$AV9)+(TER!$D$6:$D$132="")))} -> 0 | AU9: =ROUNDDOWN(AT9*AV9,0) -> 0 | AV9: =Y9-AC9-AD9-AH9-AI9 -> 1714714.5 | AX9: Terdaftar | AY9: Terdaftar | AZ9: 3600000 | BF9: =($BE9*2)-(0.5*$BD9) -> 0 | BG9: =ROUND(L9/173,2) -> 38901.02
B17: TOTAL | L17: =SUM(L6:L15) -> 29459752 | N17: =SUM(N6:N15) -> 72440.076 | O17: =SUM(O6:O15) -> 57952.061 | P17: =SUM(P6:P15) -> 893427.6 | Q17: =SUM(Q6:Q15) -> 482933.84 | R17: =SUM(R6:R15) -> 1178390.1 | S17: =SUM(S6:S15) -> 0 | T17: =SUM(T6:T15) -> 500000 | U17: =SUM(U6:U15) -> 1121052.6 | ... AM17: =SUM(AM6:AM15) -> 24354340 | AU17: =SUM(AU6:AU15) -> 394406 | AV17: =SUM(AV6:AV15) -> 27076527
AG23: UMR | AH23: 5161769
L25: 5161769

Sheet Slip Gaji
A1: SLIP GAJI
A6: Perusahaan | B6: : | C6: =Salary!$A$1 -> PT. Kalapa Teknologi Putera | G6: Bank Penerima | J6: : | K6: =IFERROR(VLOOKUP($C$8,Salary!$B$6:$BG$16,38,FALSE),"")
A7: Periode | B7: : | C7: =Salary!$B$2 -> 46113 | G7: Nama Rekening Penerima | J7: : | K7: =IFERROR(VLOOKUP($C$8,Salary!$B$6:$BG$16,40,FALSE),"")
A8: Karyawan | B8: : | C8: Yuski Hernando | G8: No.Rekening Penerima | J8: : | K8: =IFERROR(VLOOKUP($C$8,Salary!$B$6:$BG$16,41,FALSE),"")
A9: Posisi | B9: : | C9: =IFERROR(VLOOKUP($C$8,Salary!$B$6:$BG$16,5,FALSE),"")
A10: Departemen | B10: : | C10: =IFERROR(VLOOKUP($C$8,Salary!$B$6:$BG$16,6,FALSE),"")
A11: ID Karyawan | B11: : | C11: =IFERROR(VLOOKUP($C$8,Salary!$B$6:$BG$16,2,FALSE),"")
A14: Penerimaan: | G14: Pemotongan:
A15: Gaji Pokok | E15: =IFERROR(VLOOKUP($C$8,Salary!$B$6:$BG$16,11,FALSE),0) -> 0 | G15: Tunjangan BPJS Ketenagakerjaan (Dibayarkan Perusahaan kepada BPJS)
A16: Tunjangan BPJS Ketenagakerjaan | G16: JHT (Jaminan Hari Tua) | L16: =IFERROR(VLOOKUP($C$8,Salary!$B$6:$BG$16,27,FALSE),0) -> 0
A17: JHT (Jaminan Hari Tua) | E17: =IFERROR(VLOOKUP($C$8,Salary!$B$6:$BG$16,14,FALSE),0) -> 0 | G17: JKM (Jaminan Kematian) | L17: =IFERROR(VLOOKUP($C$8,Salary!$B$6:$BG$16,24,FALSE),0) -> 0
A18: JKM (Jaminan Kematian) | E18: =IFERROR(VLOOKUP($C$8,Salary!$B$6:$BG$16,12,FALSE),0) -> 0 | G18: JKK (Jaminan Kecelakaan Kerja) | L18: =IFERROR(VLOOKUP($C$8,Salary!$B$6:$BG$16,25,FALSE),0) -> 0
A19: JKK (Jaminan Kecelakaan Kerja) | E19: =IFERROR(VLOOKUP($C$8,Salary!$B$6:$BG$16,13,FALSE),0) -> 0 | G19: JP (Jaminan Pensiun) | L19: =IFERROR(VLOOKUP($C$8,Salary!$B$6:$BG$16,28,FALSE),0) -> 0
A20: JP (Jaminan Pensiun) | E20: =IFERROR(VLOOKUP($C$8,Salary!$B$6:$BG$16,15,FALSE),0) -> 0 | G20: Tunjangan BPJS Ketenagakerjaan (Dibayarkan Karyawan kepada BPJS)
A21: Tunjangan BPJS Kesehatan | E21: =IFERROR(VLOOKUP($C$8,Salary!$B$6:$BG$16,16,FALSE),0) -> 0 | G21: JHT (Jaminan Hari Tua) | L21: =IFERROR(VLOOKUP($C$8,Salary!$B$6:$BG$16,26,FALSE),0) -> 0
A22: Tunjangan Transport | E22: =IFERROR(VLOOKUP($C$8,Salary!$B$6:$BG$16,18,FALSE),0) -> 0 | G22: JP (Jaminan Pensiun) | L22: =IFERROR(VLOOKUP($C$8,Salary!$B$6:$BG$16,29,FALSE),0) -> 0
A23: Biaya Lembur | E23: =IFERROR(VLOOKUP($C$8,Salary!$B$6:$BG$16,22,FALSE),0) -> 0 | G23: Tunjangan BPJS Kesehatan (Perusahaan) | L23: =IFERROR(VLOOKUP($C$8,Salary!$B$6:$BG$16,30,FALSE),0) -> 0
A24: Tunjangan Pajak (PPh 21) | E24: =IFERROR(VLOOKUP($C$8,Salary!$B$6:$BG$16,21,FALSE),0) -> 0 | G24: Tunjangan BPJS Kesehatan (Karyawan) | L24: =IFERROR(VLOOKUP($C$8,Salary!$B$6:$BG$16,31,FALSE),0) -> 0
A25: Tunjangan Lainnya | E25: =VLOOKUP(C8,Salary!$B$6:$S$16,17,0)+VLOOKUP(C8,Salary!$B$6:$V$16,20,0) -> #N/A | G25: Ketidakhadiran ( Sakit Tanpa SKD/Ijin/Alpha) | L25: =IFERROR(VLOOKUP($C$8,Salary!$B$6:$BG$16,32,FALSE),0) -> 0
G26: Potongan Lainnya | L26: =VLOOKUP($C$8,Salary!$B$6:$AI$16,33,0) -> #N/A
A28: Total Penerimaan | E28: =SUM(E15:E26) -> #N/A | G28: Total Pemotongan | L28: =SUM(L15:L26) -> #N/A
G30: Pajak PPh 21 | L30: =IFERROR(VLOOKUP($C$8,Salary!$B$6:$BG$16,35,FALSE),0) -> 0
A33: Total Gaji Bersih / Take Home Pay | L33: =IF(E28-L28-L30=IFERROR(VLOOKUP($C$8,Salary!$B$6:$BG$16,37,FALSE),0),E28-L28-L30,"C H E C K") -> #N/A
A35: Ket:
A36: 1 | B36: ="Jumlah Hari Kerja "&TEXT($C$7,"MMMM")&" = "&TEXT(Salary!$B$3,"00")&" Hari" -> Jumlah Hari Kerja April = 19 Hari
A40: Tertanda
A45: =C6 -> PT. Kalapa Teknologi Putera

Sheet TER
A5: Jenis TER | B5: Penghasilan Bruto | E5: TER | G5: Deskripsi | H5: Jenis TER
A6: TER A | B6: 0 | C6: s.d | D6: 5400000 | E6: 0 | G6: TK/0 | H6: TER A
A7: TER A | B7: =D6 -> 5400000 | C7: s.d | D7: 5650000 | E7: 0.0025 | G7: TK/1 | H7: TER A
A8: TER A | B8: =D7 -> 5650000 | C8: s.d | D8: 5950000 | E8: 0.005 | G8: K/0 | H8: TER A
A9: TER A | B9: =D8 -> 5950000 | C9: s.d | D9: 6300000 | E9: 0.0075 | G9: TK/2 | H9: TER B
A10: TER A | B10: =D9 -> 6300000 | C10: s.d | D10: 6750000 | E10: 0.01 | G10: TK/3 | H10: TER B
A11: TER A | B11: =D10 -> 6750000 | C11: s.d | D11: 7500000 | E11: 0.0125 | G11: HB/0 | H11: TER A
A12: TER A | B12: =D11 -> 7500000 | C12: s.d | D12: 8550000 | E12: 0.015 | G12: HB/1 | H12: TER A
A13: TER A | B13: =D12 -> 8550000 | C13: s.d | D13: 9650000 | E13: 0.0175 | G13: HB/2 | H13: TER B
A14: TER A | B14: =D13 -> 9650000 | C14: s.d | D14: 10050000 | E14: 0.02 | G14: HB/3 | H14: TER B
A15: TER A | B15: =D14 -> 10050000 | C15: s.d | D15: 10350000 | E15: 0.0225 | G15: K/1 | H15: TER B
A16: TER A | B16: =D15 -> 10350000 | C16: s.d | D16: 10700000 | E16: 0.025 | G16: K/2 | H16: TER B
A17: TER A | B17: =D16 -> 10700000 | C17: s.d | D17: 11050000 | E17: 0.03 | G17: K/3 | H17: TER C
A18: TER A | B18: =D17 -> 11050000 | C18: s.d | D18: 11600000 | E18: 0.035
A19: TER A | B19: =D18 -> 11600000 | C19: s.d | D19: 12500000 | E19: 0.04
A20: TER A | B20: =D19 -> 12500000 | C20: s.d | D20: 13750000 | E20: 0.05
A21: TER A | B21: =D20 -> 13750000 | C21: s.d | D21: 15100000 | E21: 0.06
A22: TER A | B22: =D21 -> 15100000 | C22: s.d | D22: 16950000 | E22: 0.07
A23: TER A | B23: =D22 -> 16950000 | C23: s.d | D23: 19750000 | E23: 0.08
A24: TER A | B24: =D23 -> 19750000 | C24: s.d | D24: 24150000 | E24: 0.09
A25: TER A | B25: =D24 -> 24150000 | C25: s.d | D25: 26450000 | E25: 0.1
A26: TER A | B26: =D25 -> 26450000 | C26: s.d | D26: 28000000 | E26: 0.11
A27: TER A | B27: =D26 -> 28000000 | C27: s.d | D27: 30050000 | E27: 0.12
A28: TER A | B28: =D27 -> 30050000 | C28: s.d | D28: 32400000 | E28: 0.13
A29: TER A | B29: =D28 -> 32400000 | C29: s.d | D29: 35400000 | E29: 0.14
... A48: TER A | B48: =D47 -> 910000000 | C48: s.d | D48: 1400000000 | E48: 0.33
A49: TER A | B49: 1400000000 | E49: 0.34
A51: TER B | B51: 0 | C51: s.d | D51: 6200000 | E51: 0
A52: TER B | B52: =D51 -> 6200000 | C52: s.d | D52: 6500000 | E52: 0.0025
A53: TER B | B53: =D52 -> 6500000 | C53: s.d | D53: 6850000 | E53: 0.005
A54: TER B | B54: =D53 -> 6850000 | C54: s.d | D54: 7300000 | E54: 0.0075
A55: TER B | B55: =D54 -> 7300000 | C55: s.d | D55: 9200000 | E55: 0.01
A56: TER B | B56: =D55 -> 9200000 | C56: s.d | D56: 10750000 | E56: 0.015
A57: TER B | B57: =D56 -> 10750000 | C57: s.d | D57: 11250000 | E57: 0.02
A58: TER B | B58: =D57 -> 11250000 | C58: s.d | D58: 11600000 | E58: 0.025
A59: TER B | B59: =D58 -> 11600000 | C59: s.d | D59: 12600000 | E59: 0.03
A60: TER B | B60: =D59 -> 12600000 | C60: s.d | D60: 13600000 | E60: 0.04
A61: TER B | B61: =D60 -> 13600000 | C61: s.d | D61: 14950000 | E61: 0.05
A62: TER B | B62: =D61 -> 14950000 | C62: s.d | D62: 16400000 | E62: 0.06
A63: TER B | B63: =D62 -> 16400000 | C63: s.d | D63: 18450000 | E63: 0.07
...
